Workbook
Name Mode: #REF!
Name Mode: #REF!
Name Mode: #REF!
Name Mode: #REF!

Sheet Instruments
A1: Equipment 设备 | C1: Type 型号 | D1: SN / Test Condition 序列号 / 测试条件 | E1: Comments 说明
A2: DUT 被测端 | B2: Motor ( A ) 负载端电机 | C2: M24P5-S-18XXYY | D2: A01-001-180515 | E2: Potting Motor
B3: Inverter ( A ) 逆变器 | C3: RMS PM250DZR | D3: 063 | E3: RMS PM250DZR, Cont. current 450Arms, Peak current 600Arms
B4: Flowmeters ( A ) 流量计 | C4: FTB4700 | D4: None | E4: FTB4700 SERIES LOW FLOW METER
B5: Pressure Sensors ( A ) 压力传感器 | C5: SSI-P51-15-G-UC-I36-20mA-000-000 | D5: 152931214 | E5: -
A6: Oscilloscope 示波器 | B6: IWATSU AC current sensor 交流电流传感器 | C6: BB167140153 | E6: Peak current 1200A, Sensitivity 5mV/A
B7: High Voltage differential Probe ( Front ) 高压差分探头 ( 前 ) | E7: TELEDYNE LECROR HVD3102 1500VPK
B8: High Voltage differential Probe ( Rear ) 高压差分探头 ( 后 ) | E8: TELEDYNE LECROR HVD3102 1500VPK
A9: Power Cabinet 动力来源 | C9: MES50KWDCPS | D9: `2016-03-1 | E9: -
A10: Power Analyser 动力分析仪 | B10: PPA AC Current clamp - U PPA交流钳-U | D10: None
B11: PPA AC Current clamp - V PPA交流钳-V | D11: None
B12: PPA AC Current clamp - W PPA交流钳-W | D12: None
B13: PPA DC Current clamp - DUT PPA直流电流前 | D13: None
A14: Dynamometer 测功端 | B14: Motor ( B ) 负载端电机 | C14: REMY HVH250 | D14: FSCC2204-1 | E14: Remy HVH250 - 115D
B15: Inverter ( B ) 逆变器 | C15: RMS PM250DZR | D15: 170 | E15: RMS PM250DZR, Cont. current 450Arms, Peak current 600Arms
B16: Flowmeters ( B ) 流量计 | C16: FTB4700 | D16: None | E16: FTB4700 SERIES LOW FLOW METER
B17: Pressure Sensors ( B ) 压力传感器 | C17: None Monitoring | D17: None | E17: -
A18: Torquemeter 扭矩传感器 | C18: HBM T40B | D18: None | E18: HBM T40B Nominal Speed 10000-20000rpm, accuracy class 0.05 voltage ±10V current 4-20 MA
A19: Vibration Sensor 振动传感器 | D19: None
A20: Notes: 1. The purpose of this table is to follow up the status of each test instrument (signal sensitivity, calibration…), test team should be updated it with a certain period. 这个表的目的是跟踪每个测试仪器的状态(信号灵敏度校准…)，测试团队应该规律性更新。

Sheet Test Summary
A1: Num. | B1: Test Items | D1: Unit | E1: Conditions
A4: 1 | B4: Winding Resistance & Insulation | C4: winding resistance(Target value) | D4: [mΩ] | E4: @20℃
C5: winding resistance(Test value) | D5: [mΩ] | F5: =('IR measure'!A11+'IR measure'!C11+'IR measure'!F11)/3
C6: Difference between test value and target value | D6: [mΩ] | F6: =F5-F4
C7: insulation resistance | D7: [GΩ] | E7: @1000VDC,60sec &20℃ | F7: ='IR measure'!I11
C8: corrected IR | D8: [GΩ] | E8: @1000VDC,60sec &40℃ | F8: ='IR measure'!H7
C9: DAR(60 seconds/30seconds) | D9: [] | F9: ='IR measure'!E7
C10: IR Hipot test | D10: [GΩ] | E10: @3505VDC | F10: ='IR measure'!L11
C11: Surge test | D11: [] | E11: @1744V | F11: Pass
A12: 2 | B12: Resolver Offset (Electric Angle) | D12: [Deg] | E12: Motor_Type_Options: 50 MCU A B C to Motor U V W DUT Feedback speed: 1000rpm | F12: ='6. PM Parameters Setup'!M28
A13: 3 | B13: Front & Rear Stator BEMF | C13: Front Stator | D13: [Vrms_peak_peak] | E13: 1000rpm | F13: ='2.Circuiting I & 3.Drag Nm'!D5
C14: Rear Stator | D14: [Vrms_peak_peak] | F14: ='2.Circuiting I & 3.Drag Nm'!E5
C15: Voltage Difference | D15: [Vrms] | F15: =F14-F13
A16: 4 | B16: Recirculating Current | D16: [Arms] | E16: 4000rpm | F16: ='2.Circuiting I & 3.Drag Nm'!E15
A17: 5 | B17: No Load Torque | D17: [Nm] | E17: 4000rpm | F17: ='2.Circuiting I & 3.Drag Nm'!D26
A18: 6 | B18: Motor Back EMF | C18: BEMF Constant Ke(Targgt value) | D18: [Vrms_ph-ph/(rad/s)] | E18: Coolant 55°C, 1000rpm
C19: BEMF Constant Ke(Test value) | D19: [Vrms_ph-ph/(rad/s)] | F19: ='4.Motor BEMF'!E25
C20: Difference between test value and target value | D20: [%] | F20: =1-(F19/F18)
A21: 7 | B21: Short - Circuit | C21: Phase U Current | D21: [Arms] | E21: Coolant 55°C, 8lpm, 4000rpm | F21: ='5. Short circuit'!M10
C22: Phase V Current | D22: [Arms] | F22: ='5. Short circuit'!M12
C23: Phase W Current | D23: [Arms] | F23: ='5. Short circuit'!M14
C24: Torque | D24: [Nm] | F24: ='5. Short circuit'!M20
A25: 8 | B25: Motor Torque vs. Phase Current | C25: Maximum Motor Torque(Targgt value) | D25: [Nm] | E25: Coolant 55°C, 500rpm
C26: Maximum Motor Torque(Test value) | D26: [Nm] | F26: ='7. Torque vs. Phase Current'!K16
C27: Difference between test value and target value | D27: [%] | F27: =1-F26/F25
C28: Torque Constant Kt | D28: [Nm/Arms] | E28: 50Arms(Targgt value)
E29: 50Arms(Test value) | F29: ='7. Torque vs. Phase Current'!E17
E30: Difference between test value and target value[%] | F30: =1-F29/F28
E31: 150Arms | F31: ='7. Torque vs. Phase Current'!G17
E32: 350Arms | F32: ='7. Torque vs. Phase Current'!K16
A33: 9 | B33: Winding Heating | C33: ∆T after 8mins RTD1 | D33: [°C] | E33: Heating from 60°C, 100Arms, 500rpm, Coolant 55°C, 8lpm | F33: ='8. Winding Heating'!E21
C34: ∆T after 8mins RTD2 | F34: ='8. Winding Heating'!G21
A35: 10 | B35: Continue Torque Measurement | C35: Continuous Torque (Target value) | D35: [Nm] | E35: 500rpm, 600VDC, Max. Twinding: 150°C, Coolant 55°C, 8lpm
C36: Continuous Torque (Test value) | D36: [Nm] | F36: ='9. Cont. Torque Curve'!G27
C37: Difference between test value and target value | D37: [%] | F37: =1-F36/F35
C38: Continuous Current | D38: [Arms] | F38: ='9. Cont. Torque Curve'!G38
C39: Continuous Power | D39: [kW] | F39: ='9. Cont. Torque Curve'!G40
C40: Efficiency | D40: [] | F40: ='9. Cont. Torque Curve'!G52
C41: Torque Constant Kt | D41: [Nm/Arms] | F41: ='9. Cont. Torque Curve'!G49
C42: Winding temp. Diff. | D42: [°C] | F42: =ABS('9. Cont. Torque Curve'!G22-'9. Cont. Torque Curve'!G23)
...

Sheet DUT Description
B1: PRODUCT ACCEPTANCE TEST - DUT DESCRIPTION
B2: =C6&" - "&D6
A3: Name of Tester 1: 测试人员1 | B3: Name of Tester 2: 测试人员2 | C3: Test Room Temperature 测试房温度 (゜C ) | D3: Test Room Humidity 测试房湿度( % ) | E3: Test Data: 测试日期
A5: DUT Motor 被测电机 | B5: Product Number 产品号码 | C5: Model 型号 | D5: Code 代码 | E5: Motor Comment 电机描述
A7: Motor & MCU Configuration 电机和逆变器配置 --------------------------- MCU Resolver Calibration 逆变器旋变标定 | B7: Model 型号 | C7: Serial No. 序列号 | D7: Number of Poles for Motor 电机极对数 | E7: Number of Poles for Resolver 旋变极对数
B9: Phase Cables Connection 相电缆连接 | C9: Motor_Type_Options_EEPROM 电机类型选项EEPROM | D9: Dyno Speed Command [rpm] 测功机速度 | E9: Dyno Feedback Speed [rpm] 测功机反馈速度
B10: Motor U V W to MCU A B C | C10: 50 | D10: 1000 | E10: -1000
B11: DUT Feedback Speed [rpm] 被测电机反馈速度 | C11: Voltage Feedback Speed [rpm] 电压反馈转速 | D11: DUT Forward Direction 电机前进方向 | E11: Resolver Offset_X_10 (Electric Angle) 旋变补偿值 ( 电角 )
B12: 1000 | C12: 1000 | D12: Clockwise顺时针旋转
A13: 1. The purpose of this tab is to describe the general information of the DUT and test rig config 文件目的是描述被测电机的一般信息和测试设备配置 2. The format of the spreadsheet: "Motor model" - "Motor code" 表格的格式:“电机型号”—“电机代码” 3. Resolver Offset_X_10 (Electric Angle) should be between ±3600, even better ±1800 旋变补偿值需要在±3600之间,最好在±1800 | G13: s
A14: Version 版本 | B14: Description of Versions / Changes 版本描述 / 更改 | D14: updated by 更新者 | E14: Data 日期
A15: 0 | B15: First virsion to release this spreadsheet | D15: Leslie Wu | E15: 43087
A16: 1 | B16: Updated protection cell - release the access to modify test conditions Updated DUT Description - Resolver calibration Updated the data source for PM Parameters Setup calculation Added test item - work area check Added "notes" cell to recored note during testing | D16: Leslie Wu | E16: 43096
A17: 1.0-1 | B17: Just adjust the format | D17: York | E17: 43266

Sheet Pt100 check&Hipot test
A2: Pt100 Check Before PAT Test
A3: Motor Winding Temp. | C3: Pin1&2 | D3: PIN 2 & Spare red line | E3: Pin 3&4 | F3: PIN 3 & Spare red line
A4: RPT100 | B4: [Ω] | D4: - | F4: -
A5: TPT100 | B5: [°C] | C5: =IF(C4="","",2.597114*C4-259.528294) | D5: - | E5: =IF(E4="","",2.597114*E4-259.528294) | F5: -
A6: Read From SW | D6: - | F6: -
A10: Hipot test Summary

Sheet IR measure
C1: PRODUCT ACCEPTANCE TEST - IR MEASURE
C2: ='DUT Description'!C6&" - "&'DUT Description'!D6
A3: Statue 位置 | B3: Voltage Range 电压量程 | C3: R15 sec 电阻 | D3: R60 sec 电阻 | E3: DAR 吸收比 | F3: Tmeasurement 温度测量 | G3: R15 sec 40°C 电阻 | H3: R60 sec 40°C 电阻 | I3: RTD1 电阻1 | J3: RTD2 电阻2 | K3: RT 室温 | L3: RH 湿度 | M3: Tester 1 测试人员
B4: V | C4: [GΩ] | D4: [GΩ] | E4: [ ] | F4: [°C] | G4: [GΩ] | H4: [GΩ] | I4: [Ω] | J4: [Ω] | K4: [°C] | L4: [%]
A5: Front stator 前定子 | B5: 1000
A6: Rear stator 后定子 | B6: 1000
A7: Motor 电机 | B7: 1000 | E7: =IF(D7="",NA(),D7/C7) | F7: 26 | G7: =IF(C7="",NA(),C7*0.5^((40-F7)/10)) | H7: =IF(D7="",NA(),D7*0.5^((40-F7)/10))
A9: Winding Resistance 绕组阻值 ( mohm ) | I9: Insulation Resistance & DAR 绝缘电阻&吸收比 ( Gohm ) | L9: HIPOT DC 直流高压 ( GOhm )
A10: Winding phase 1-2 1-2相 | C10: Winding phase 2-3 2-3相 | F10: Winding phase 3-1 3-1相 | I10: 1005V | L10: 3005V
A12: DAR (吸收比)： 在同一次试验中，60s时的绝缘电阻值与15s时的绝缘电阻值之比。 目的: 为了发现绝缘受潮。除反映绝缘受潮情况外，还能反映整体和局部缺陷。 变压器大修后在进行的电气试验项目之一就是测量绕组的绝缘电阻和吸收比。 《国家电网山东电力集团公司2007版电力设备交接和预防性试验规程》对吸收比有如下规定：吸收比在常温下不低于1.3；当R60s(60秒时的电阻)大于3000MΩ时，吸收比可不做考核要求。
B13: Automatic calculate 自动计算

Sheet 2.Circuiting I & 3.Drag Nm
D1: PRODUCT ACCEPTANCE TEST - CIRCUITING I & DRAG N.M
D2: ='DUT Description'!C6&" - "&'DUT Description'!D6
A3: Item 1. BEMF Measurement 反电动势测量 | B3: Step 步骤 | C3: Motor Speed 电机速度 | D3: Front Stator BEMF Voltage 前定子反电动势电压 | E3: Rear Stator BEMF Voltage 后定子反电动势电压 | F3: Voltage Diff. 电压差 | G3: Time Diff. @Zero Cross Point 反电动势零点漂移 | H3: Notes: Test 1 Propose 1. The purpose of this test is to make sure the BEMF ( Back Electromotive Force ) of both stators are within the target limits. In both amplitude and phase. 此测试程序的目的是要确保反电动势(电动势)两个绕组匝在目标范围之内。在这两个振幅和相位。 2. If not, corrective action should be taken. 如果没有,应采取纠正措施。 3. To correct amplitude, airgap must be adjusted. 调节气息到正确的幅值 4. To correct phase, stator angle must be adjusted. 调节定子角度到正确的相位
C4: [rpm] | D4: [Vrms_peak_peak] | E4: [Vrms_peak_peak] | F4: [Vrms] | G4: [us]
B5: 1 | C5: 1000 | F5: =ABS(D5-E5)
B6: 2 | C6: 1000 | F6: =ABS(D6-E6)
B7: 3 | C7: 1000 | F7: =ABS(D7-E7)
B8: 4 | C8: 1000 | F8: =ABS(D8-E8)
A10: Item 2. Recirculating Currents Measurement 环流测量 | B10: Step 步骤 | C10: Motor Speed 电机速度 | D10: Current Sensor Output Voltage 电流传感器输出电压 | E10: Circulating Current 环流 | F10: Max. Motor Temp. 电机最高温度 | G10: Notes: Test 2 Propose 1.After correct airgap / stators angle circulating currents need to be checked to make sure the measurement is within the target limits. 检查正确后的气隙 / 定子角度循环电流以确保测量是在目标范围内。 2. If limits are exceeded, re-adjustment needs to be made. 如果超出限制,需要再次调整
C11: [rpm] | D11: [mV_peak_peak] | E11: [Arms] | F11: [℃]
B12: 1 | C12: 1000 | E12: =D12/5/2/SQRT(2)
B13: 2 | C13: 2000 | E13: =D13/5/2/SQRT(2)
B14: 3 | C14: 3000 | E14: =D14/5/2/SQRT(2)
B15: 4 | C15: 4000 | E15: =D15/5/2/SQRT(2)
A17: Item 3. No Load Torque Measurement 空载扭矩测量 | B17: Step 步骤 | C17: Speed 速度 | D17: Torque Average 平均转矩 | E17: Torque Peak 峰值扭矩 | F17: Notes: Test 3 Propose 1. The puepose of this test is to measure the no load power loss at different speed 这个测试的目的是测量不同转速下的空载功率损耗
C18: [rpm] | D18: [Nm] | E18: [Nm]
B19: 1 | C19: 50
B20: 2 | C20: 100
B21: 3 | C21: 250
B22: 4 | C22: 750
B23: 5 | C23: 1000
B24: 6 | C24: 2000
B25: 7 | C25: 3000
B26: 8 | C26: 4000
B27: 9 | C27: 5000
B28: 10 | C28: 6000
B29: 11 | C29: -500
B30: 12 | C30: -2000
A31: Notes:
A32: 1. No coolant and no HV cable connect during test the dut motor 必须无冷却，电机必须不接线
B33: Automatic calculate 自动计算

Sheet 4.Motor BEMF
C1: PRODUCT ACCEPTANCE TEST - BACK ELECTROMOTIVE FORCE
C2: ='DUT Description'!C6&" - "&'DUT Description'!D6
A3: Coollant and Test Room Environment 冷却系统和测试环境
A4: D.U.T. Control Mode 被测电机控制模式 | C4: Rotating Direction 运转方向 | E4: Coolant Temperature 冷却介质温度 | G4: Winding Temperature 绕线温度 | I4: RT 室温 | J4: RH 湿度
E5: [°C] | G5: [°C] | I5: [°C] | J5: [%]
A6: Disable 禁用 | C6: Positive正转 | E6: 55 | G6: 55 | I6: ='DUT Description'!C4 | J6: ='DUT Description'!D4
A8: Items 4. Motor BEMF Measurement 电机反电动势测量 | I8: Test Propose: 1. The purpose of this test is to know Ke parameter of DUT and phase voltage deviation. 目的是要知道被测电机的Ke参数和相电压偏差。
A9: Mechanical Data 机械参数 | B9: Speed Set Point 设定速度 | D9: [rpm] | E9: 1000 | F9: 2000 | G9: 3000 | H9: 4000
B10: Speed Reading @ Inverter Feedback 逆变器反馈速度 | D10: [rpm] | E10: 1000 | F10: 2000 | G10: 3000 | H10: 4000
B11: Speed Reading @ Inverter Feedback 逆变器反馈速度 | D11: [rad/s] | E11: =E10/60*2*PI() | F11: =F10/60*2*PI() | G11: =G10/60*2*PI() | H11: =H10/60*2*PI()
B12: Frequency 频率 | D12: [Hz] | E12: =E10*'DUT Description'!D8/60 | F12: =F10*'DUT Description'!D8/60 | G12: =G10*'DUT Description'!D8/60 | H12: =H10*'DUT Description'!D8/60
A14: Electrical Data 电参数 | B14: Motor Output Voltage ph-n [VRMS] 电机输出电压 | D14: Phase U
D15: Phase V
D16: Phase W
D17: Average | E17: =AVERAGE(E14:E16) | F17: =AVERAGE(F14:F16) | G17: =AVERAGE(G14:G16) | H17: =AVERAGE(H14:H16)
B18: Deviation (Ph-n) 偏差 | E18: =MAX(ABS(E14-E15),ABS(E14-E16),ABS(E15-E16))/E17 | F18: =MAX(ABS(F14-F15),ABS(F14-F16),ABS(F15-F16))/F17 | G18: =MAX(ABS(G14-G15),ABS(G14-G16),ABS(G15-G16))/G17 | H18: =MAX(ABS(H14-H15),ABS(H14-H16),ABS(H15-H16))/H17
B19: Ke [Vrms_ph-n/(rad/s)] | E19: =E17/E11 | F19: =F17/F11 | G19: =G17/G11 | H19: =H17/H11
B20: Motor Output Voltage ph-ph [VRMS] 电机输出电压 | D20: Phase UV
D21: Phase VW
D22: Phase WU
D23: Average | E23: =AVERAGE(E20:E22) | F23: =AVERAGE(F20:F22) | G23: =AVERAGE(G20:G22) | H23: =AVERAGE(H20:H22)
B24: Deviation (Ph-Ph) 偏差 | E24: =MAX(ABS(E20-E21),ABS(E20-E22),ABS(E21-E22))/E23 | F24: =MAX(ABS(F20-F21),ABS(F20-F22),ABS(F21-F22))/F23 | G24: =MAX(ABS(G20-G21),ABS(G20-G22),ABS(G21-G22))/G23 | H24: =MAX(ABS(H20-H21),ABS(H20-H22),ABS(H21-H22))/H23
B25: Ke [Vrms_ph-ph/(rad/s)] | E25: =E20/E11 | F25: =F20/F11 | G25: =G20/G11 | H25: =H20/H11
B26: Oscilloscope Value @ 1000rpm 1000转时示波器波形数据
B27: Automatic calculate 自动计算

Sheet 5. Short circuit
C1: PRODUCT ACCEPTANCE TEST - SHORT CIRCUIT
C2: ='DUT Description'!C6&" - "&'DUT Description'!D6
A3: Coollant and Test Room Environment 冷却系统和测试环境
A4: D.U.T. Control Mode 被测电机控制模式 | C4: Rotating Direction 运转方向 | E4: Coolant Temperature 冷却介质温度 | I4: Winding Temp. Range 绕线温度目标范围 | L4: RT 室温 | N4: RH 湿度
E5: [°C] | I5: [°C] | L5: [°C] | N5: [%]
A6: Disenable 禁用 | C6: Positive正转 | E6: 55 | I6: 55 - 90 | L6: 24.3 | N6: 74.7
A8: Item 5. Short - Circuit Measurement 短路测量
A9: Speed [rpm] 速度 | D9: 100 | E9: 200 | F9: 300 | G9: 400 | H9: 500 | I9: 750 | J9: 1000 | K9: 2000 | L9: 3000 | M9: 4000 | N9: Test Propose 1. the purpose of this test is to check inductance of each phase and inductance difference between phases. 测试目的是检查每相电感和不同相间的电感。
A10: Phase U Current U相电流 | C10: [Arms] | J10: 190.4 | K10: 193.32 | L10: 193.94 | M10: 194.12
C11: Fundamental [Arms] | J11: 190.31 | K11: 193.23 | L11: 193.92 | M11: 194.05
A12: Phase V Current V相电流 | C12: [Arms] | J12: 191.95 | K12: 196.21 | L12: 197.26 | M12: 197.61
C13: Fundamental [Arms] | J13: 191.86 | K13: 196.12 | L13: 197.25 | M13: 197.55
A14: Phase W Current W相电流 | C14: [Arms] | J14: 200.26 | K14: 203.93 | L14: 204.62 | M14: 204.79
C15: Fundamental [Arms] | J15: 200.16 | K15: 203.84 | L15: 204.6 | M15: 204.72
A16: Average 平均值 | C16: [Arms] | D16: =AVERAGE(D10,D12,D14) | E16: =AVERAGE(E10,E12,E14) | F16: =AVERAGE(F10,F12,F14) | G16: =AVERAGE(G10,G12,G14) | H16: =AVERAGE(H10,H12,H14) | I16: =AVERAGE(I10,I12,I14) | J16: =AVERAGE(J10,J12,J14) | K16: =AVERAGE(K10,K12,K14) | ... M16: =AVERAGE(M10,M12,M14)
C17: Fundamental [Arms] | D17: =AVERAGE(D11,D13,D15) | E17: =AVERAGE(E11,E13,E15) | F17: =AVERAGE(F11,F13,F15) | G17: =AVERAGE(G11,G13,G15) | H17: =AVERAGE(H11,H13,H15) | I17: =AVERAGE(I11,I13,I15) | J17: =AVERAGE(J11,J13,J15) | K17: =AVERAGE(K11,K13,K15) | ... M17: =AVERAGE(M11,M13,M15)
A18: Deviation 偏差 | C18: [%] | D18: =MAX(ABS(D10-D12),ABS(D10-D14),ABS(D12-D14))/D16 | E18: =MAX(ABS(E10-E12),ABS(E10-E14),ABS(E12-E14))/E16 | F18: =MAX(ABS(F10-F12),ABS(F10-F14),ABS(F12-F14))/F16 | G18: =MAX(ABS(G10-G12),ABS(G10-G14),ABS(G12-G14))/G16 | H18: =MAX(ABS(H10-H12),ABS(H10-H14),ABS(H12-H14))/H16 | I18: =MAX(ABS(I10-I12),ABS(I10-I14),ABS(I12-I14))/I16 | J18: =MAX(ABS(J10-J12),ABS(J10-J14),ABS(J12-J14))/J16 | K18: =MAX(ABS(K10-K12),ABS(K10-K14),ABS(K12-K14))/K16 | ... M18: =MAX(ABS(M10-M12),ABS(M10-M14),ABS(M12-M14))/M16
C19: Fundamental [%] | D19: =MAX(ABS(D11-D13),ABS(D11-D15),ABS(D13-D15))/D17 | E19: =MAX(ABS(E11-E13),ABS(E11-E15),ABS(E13-E15))/E17 | F19: =MAX(ABS(F11-F13),ABS(F11-F15),ABS(F13-F15))/F17 | G19: =MAX(ABS(G11-G13),ABS(G11-G15),ABS(G13-G15))/G17 | H19: =MAX(ABS(H11-H13),ABS(H11-H15),ABS(H13-H15))/H17 | I19: =MAX(ABS(I11-I13),ABS(I11-I15),ABS(I13-I15))/I17 | J19: =MAX(ABS(J11-J13),ABS(J11-J15),ABS(J13-J15))/J17 | K19: =MAX(ABS(K11-K13),ABS(K11-K15),ABS(K13-K15))/K17 | ... M19: =MAX(ABS(M11-M13),ABS(M11-M15),ABS(M13-M15))/M17
A20: Torque 扭矩 | C20: [Nm] | J20: -37.27 | K20: -20.86 | L20: -15.21 | M20: -11.67
A21: Motor Temp. 电机温度 | C21: [°C] | J21: 42.2 | K21: 57.2 | L21: 75 | M21: 88.6
A22: Power 功率 | C22: [Kw] | D22: =D9*D20*2*PI()/60/1000 | E22: =E9*E20*2*PI()/60/1000 | F22: =F9*F20*2*PI()/60/1000 | G22: =G9*G20*2*PI()/60/1000 | H22: =H9*H20*2*PI()/60/1000 | I22: =I9*I20*2*PI()/60/1000 | J22: =J9*J20*2*PI()/60/1000 | K22: =K9*K20*2*PI()/60/1000 | ... M22: =M9*M20*2*PI()/60/1000
B23: Automatic calculate 自动计算

Sheet 6. PM Parameters Setup
C1: PRODUCT ACCEPTANCE TEST - PM MOTOR PARAMETERS
C2: ='DUT Description'!C6&" - "&'DUT Description'!D6
A3: Item 6. Motor Control Parameters Calculation 电机控制参数计算
A4: 1. Winding Resistance Calculation 绕组电阻计算
A5: Winding Resistance ph-ph 相间绕组阻值 ( mohm ) | D5: Winding Resistance ph-n 相间绕组阻值 ( mohm ) | G5: Average Resistance (Phase to Neutral) 平均电阻 （中性相） | I5: Deviation 偏差 | K5: Stator_Resistance_EEPROM (Ohmsx10000)
A6: Phase 1-2 | B6: Phase 2-3 | C6: Phase 3-1 | D6: Phase U | E6: Phase V | F6: Phase W
A7: ='IR measure'!A11 | B7: ='IR measure'!C11 | C7: ='IR measure'!F11 | D7: =(C7+(A7-B7))/2 | E7: =A7-D7 | F7: =B7-E7 | G7: =(D7+E7+F7)/3 | I7: =MAX(ABS(D7-E7),ABS(D7-F7),ABS(E7-F7))/G7 | K7: =G7*10
A8: 2. Motor Flux Value Calculation 电动机磁通值计算
A9: Motor Speed 电机速度 | C9: Motor Electrical Speed 电机角速度ω | E9: Neutral Voltage 中性电压[Vrms] | H9: Neutral Voltage 中性电压 | J9: Motor Flux 电机磁通 | M9: Veh_Flux_EEPROM (Wb)_x_1000
A10: [rpm] | C10: [rad/s] | E10: Phase U | F10: Phase V | G10: Phase W | H10: Average [Vpeak] | J10: [Wb] | K10: Average [Wb]
A11: 1000 | C11: =A11*2*PI()*'DUT Description'!D8/60/2 | E11: ='4.Motor BEMF'!E14 | F11: ='4.Motor BEMF'!E15 | G11: ='4.Motor BEMF'!E16 | H11: =AVERAGE(E11:G11)*SQRT(2) | J11: =H11/C11 | K11: =AVERAGE(J11:J14) | M11: =K11*1000
A12: 2000 | C12: =A12*2*PI()*'DUT Description'!D8/60/2 | E12: ='4.Motor BEMF'!F14 | F12: ='4.Motor BEMF'!F15 | G12: ='4.Motor BEMF'!F16 | H12: =AVERAGE(E12:G12)*SQRT(2) | J12: =H12/C12
A13: 3000 | C13: =A13*2*PI()*'DUT Description'!D8/60/2 | E13: ='4.Motor BEMF'!G14 | F13: ='4.Motor BEMF'!G15 | G13: ='4.Motor BEMF'!G16 | H13: =AVERAGE(E13:G13)*SQRT(2) | J13: =H13/C13
A14: 4000 | C14: =A14*2*PI()*'DUT Description'!D8/60/2 | E14: ='4.Motor BEMF'!H14 | F14: ='4.Motor BEMF'!H15 | G14: ='4.Motor BEMF'!H16 | H14: =AVERAGE(E14:G14)*SQRT(2) | J14: =H14/C14
A15: 3. Motor Inductance Calculation 电机电感计算
A16: Motor Speed 电机速度 | C16: Motor Electrical Speed 电机角速度ω | E16: Current 电流 [Arms] | H16: Inductance [H] 电感 | L16: Deviation 偏差 | M16: Ld_Lq_Const_EEPROM (uH)
A17: [rpm] | C17: [rad/s] | E17: Phase U | F17: Phase V | G17: Phase W | H17: Phase U | I17: Phase V | J17: Phase W | K17: Average
A18: 1000 | C18: =A18*2*PI()*'DUT Description'!D8/60/2 | E18: {=TRANSPOSE('5. Short circuit'!J10:M10)} | F18: {=TRANSPOSE('5. Short circuit'!J12:M12)} | G18: {=TRANSPOSE('5. Short circuit'!J14:M14)} | H18: =1/C18*SQRT((E11/E18)^2-(D7/1000)^2) | I18: =1/C18*SQRT((F11/F18)^2-(E7/1000)^2) | J18: =1/C18*SQRT((G11/G18)^2-(F7/1000)^2) | K18: =AVERAGE(H18:J18) | L18: =MAX(ABS(H18-I18),ABS(H18-J18),ABS(I18-J18))/K18 | M18: =AVERAGE(K18:K21)*1000000
A19: 2000 | C19: =A19*2*PI()*'DUT Description'!D8/60/2 | E19: 0 | F19: 0 | G19: 0 | H19: =1/C19*SQRT((E12/E19)^2-(D7/1000)^2) | I19: =1/C19*SQRT((F12/F19)^2-(E7/1000)^2) | J19: =1/C19*SQRT((G12/G19)^2-(F7/1000)^2) | K19: =AVERAGE(H19:J19) | L19: =MAX(ABS(H19-I19),ABS(H19-J19),ABS(I19-J19))/K19
A20: 3000 | C20: =A20*2*PI()*'DUT Description'!D8/60/2 | E20: 0 | F20: 0 | G20: 0 | H20: =1/C20*SQRT((E13/E20)^2-(D7/1000)^2) | I20: =1/C20*SQRT((F13/F20)^2-(E7/1000)^2) | J20: =1/C20*SQRT((G13/G20)^2-(F7/1000)^2) | K20: =AVERAGE(H20:J20) | L20: =MAX(ABS(H20-I20),ABS(H20-J20),ABS(I20-J20))/K20
A21: 4000 | C21: =A21*2*PI()*'DUT Description'!D8/60/2 | E21: 0 | F21: 0 | G21: 0 | H21: =1/C21*SQRT((E14/E21)^2-(D7/1000)^2) | I21: =1/C21*SQRT((F14/F21)^2-(E7/1000)^2) | J21: =1/C21*SQRT((G14/G21)^2-(F7/1000)^2) | K21: =AVERAGE(H21:J21) | L21: =MAX(ABS(H21-I21),ABS(H21-J21),ABS(I21-J21))/K21
A22: 4. Kp & Ki parameters for Id & Iq Current Regulators 逆变器有功电流和无功电流的比例增益Kp和积分增益Ki 电流监管
A23: W1 | C23: V_Base_EEPROM_ (Volts) | E23: I_Base_EEPROM_ (Amps) | G23: Kp | I23: Ki | K23: Kp_Current_EEPROM_ x_1000 | M23: Ki_Current_EEPROM_ x_10000
A24: =(K7/10000)/(M18/1000000) | C24: 200 | E24: 300 | G24: =(M18/1000000)*A24/(C24/E24) | I24: =G24*A24/12000 | K24: =G24*1000 | M24: =I24*10000
A25: 5. Resolver Calibration 旋变标定
A26: RMS Resolver Calibration Process RMS 旋变标定流程 | C26: Remy Speed | D26: Feedback speed | E26: Voltage_Feedback Speed | G26: Delta_Resolver_In_Fil _(DEG_x_10) | I26: Delta_Resolver_In_Fil _at_1000RPM | K26: Gamma_Adjust_(Deg) _x_10_Before | M26: Gamma_Adjust_(Deg) _x_10_updated
C27: [rpm] | D27: [rpm] | E27: [rpm]
A28: Positive Value 正转参数 | C28: 1000 | D28: 1000 | E28: 1000 | M28: =(K28/10-(90-G28/10))*10
A29: Negative Value 反转参数 | C29: 1000 | D29: -1000 | E29: -1000 | M29: =(K29/10-(-90-G29/10))*10
B30: Automatic calculate 自动计算

Sheet 7. Torque vs. Phase Current
C1: PRODUCT ACCEPTANCE TEST - Torque VS Phase Current
C2: ='DUT Description'!C6&" - "&'DUT Description'!D6
A3: Coollant and Test Room Environment 冷却系统和测试环境
A4: D.U.T. Control Mode 被测电机控制模式 | C4: Rotating Direction 运转方向 | E4: DC BUS Voltage 直流电压 | G4: Speed Set Point 速度设定点 | I4: Coolant Temperature 冷却介质温度 | K4: Winding Temp. Range 绕线温度目标范围 | M4: RT 室温 | N4: RH 湿度
E5: [VDC] | G5: [rpm] | I5: [°C] | K5: [°C] | M5: [°C] | N5: [%]
A6: Traction & Torque扭矩（主转状态） | C6: Positive正转 | E6: 600 | G6: 500 | I6: 55 | K6: 55 -120 | M6: ='DUT Description'!C4 | N6: ='DUT Description'!D4
A7: Item 7. Motor Torque vs. Phase Current Mensurement 电机扭矩VS 相电流测量
A8: Description | E8: Data 1 | F8: Data 2 | G8: Data 3 | H8: Data 4 | I8: Data 5 | J8: Data 6 | K8: Data 7 | L8: Data 8 | M8: Data 9 | N8: Data 10
A9: Phase Current Setting Point 相电流设定点 | D9: [Arms] | E9: 50 | F9: =E9+50 | G9: =F9+50 | H9: =G9+50 | I9: =H9+50 | J9: =I9+50 | K9: 350
A10: Winding Temperature @measuring 绕线温度测量值 | D10: [°C]
A11: Real Phase Current 实际相电流值 | D11: [Arms]
A12: Real Speed 实际速度 | D12: [rpm] | E12: 500 | F12: 500 | G12: 500 | H12: 500 | I12: 500 | J12: 500 | K12: 500 | L12: 500 | M12: 500 | N12: 500
A13: Real Speed 实际角速度 | D13: [rad/s] | E13: =E12/60*2*PI() | F13: =F12/60*2*PI() | G13: =G12/60*2*PI() | H13: =H12/60*2*PI() | I13: =I12/60*2*PI() | J13: =J12/60*2*PI() | K13: =K12/60*2*PI() | L13: =L12/60*2*PI() | ... N13: =N12/60*2*PI()
A14: Frequency 频率 | D14: [Hz] | E14: =E12/60*'DUT Description'!$D$8 | F14: =F12/60*'DUT Description'!$D$8 | G14: =G12/60*'DUT Description'!$D$8 | H14: =H12/60*'DUT Description'!$D$8 | I14: =I12/60*'DUT Description'!$D$8 | J14: =J12/60*'DUT Description'!$D$8 | K14: =K12/60*'DUT Description'!$D$8 | L14: =L12/60*'DUT Description'!$D$8 | ... N14: =N12/60*'DUT Description'!$D$8
A15: Torque Command [Nm] 扭矩命令值 | D15: [Nm]
A16: Torque measurement 扭矩测量值 | D16: [Nm]
A17: Kt | D17: [Nm/Arms] | E17: =E16/E11 | F17: =F16/F11 | G17: =G16/G11 | H17: =H16/H11 | I17: =I16/I11 | J17: =J16/J11 | K17: =K16/K11 | L17: =L16/L11 | ... N17: =N16/N11
A18: Ke [Vrms_ph-ph/(rad/s)] calculated by Kt | E18: =E17/SQRT(3) | F18: =F17/SQRT(3) | G18: =G17/SQRT(3) | H18: =H17/SQRT(3) | I18: =I17/SQRT(3) | J18: =J17/SQRT(3) | K18: =K17/SQRT(3) | L18: =L17/SQRT(3) | ... N18: =N17/SQRT(3)
B19: Automatic calculate 自动计算
A20: Test Propose
A21: The purpose of this test is to find 测试目的是为了寻找 1. Kt parameter for the DUT 被测电机的的Kt参数 2. How much phase current at which the motor start to saturation. 电机开始饱和电流 3. Check MCU torque control accuracy。 检查逆变器扭矩控制精度

Sheet Peak torque
C1: Description | D1: For up to 60s | E1: For up to 20s
A2: Mechanical Data | B2: Motor Test Conditions | C2: Pole pairs | D2: 5 | E2: 5
C3: Machine model
C4: M.U.T. control mode | D4: Enable | E4: Enable
C5: Type of test | D5: Peak torque | E5: Peak torque
C6: Rotating direction
C7: DC BUS Voltage [VDC] | D7: 400 | E7: 400
C8: Speed Set Point [rpm] | D8: 500 | E8: 500
C9: Ambient Room Temperature [°C] | D9: 20 | E9: 20
C10: Coolant Temp. In Motor [°C]
C11: Coolant Temp. Out Motor [°C]
C12: Winding Temp. @end [°C]
B13: Motor Speed & Torque | C13: Speed Read@Inverter Feedback [rpm] | D13: 500 | E13: 500
C14: Frequency [Hz] | D14: =D13*D2/60 | E14: =E13*E2/60
C15: Speed Read@Inverter Feedback [rad/s] | D15: 500 | E15: 500
C16: Torque Sensor Offset [VDC]
C17: Torque Sensor DC Read Value [VDC]
C18: Torque measured value [VDC] | D18: =D17-D16 | E18: =E17-E16
C19: Torque sensor Gain | D19: 100.12 | E19: 100.12
C20: Torque Read@Torque Sensor [Nm] | D20: =D19*D18 | E20: =E19*E18
C21: Motor Current ph-n [VRMS]
C22: Kt [Nm/IRMS_ph-n]

Sheet 8. Winding Heating
C1: PRODUCT ACCEPTANCE TEST - Winding Heating
C2: ='DUT Description'!C6&" - "&'DUT Description'!D6
A3: Coollant and Test Room Environment 冷却系统和测试环境
A4: D.U.T. Control Mode 被测电机控制模式 | C4: Rotating Direction 运转方向 | E4: DC BUS Voltage 直流电压 | F4: Phase Current Setting Point相电流设定 | H4: Speed Set Point 速度设定点 | J4: Coolant 冷却介质 | L4: Ambient Room Temp 环境温度
E5: [VDC] | F5: [Arms] | H5: [rpm] | J5: Temp温度 [°C] | K5: Flow流量 [L/min] | L5: [°C]
A6: Traction & Torque牵引和扭矩 | C6: Positive正转 | E6: 600 | F6: 100 | H6: 500 | J6: 55 | K6: 8 | L6: 20
A7: Item 8. Winding Heating Measurement 绕组加热测试
A8: Description | E8: Data 1- Starting | G8: Data 2 - After xx mins | K8: Time [s] | L8: Twinding [°C] | M8: Twinding [°C]
A9: Real Ambient Room Temperature 实际室温 | D9: [°C] | E9: 20 | G9: 20 | K9: Time | L9: MA_RTD1 | M9: MA_RTD2
A10: Real Motor Coolant Flow Rate 实际冷却介质流量 | D10: [lpm] | E10: 8 | G10: 8 | K10: -7
A11: Real Coolant Temp. In Motor 实际冷却介质温度 | D11: [°C] | E11: 55 | G11: 55 | K11: 1.1574074e-05
A12: Real Speed 实际速度 | D12: [rpm] | E12: 500 | G12: 500 | K12: 2.3148148e-05
A13: Real Speed 实际角速度 | D13: [rad/s] | E13: =E12/60*2*PI() | G13: =G12/60*2*PI() | K13: 3.4722222e-05
A14: Frequency 频率 | D14: [Hz] | E14: =E12/60*'DUT Description'!$D$8 | G14: =G12/60*'DUT Description'!$D$8 | K14: 4.6296296e-05
A15: Real Phase Current 实际相电流 | D15: [Arms] | K15: 5.787037e-05
A16: Torque Command 扭矩命令值 | D16: [Nm] | K16: 6.9444444e-05
A17: Torque measurement 扭矩测量值 | D17: [Nm] | K17: 8.1018519e-05
A18: Kt | D18: [Nm/Arms] | E18: =E17/E15 | G18: =G17/G15 | K18: 9.2592593e-05
A19: Winding Temperature 绕线温度 | E19: RTD1 | G19: RTD2 | K19: 0.00010416667
A20: Winding Temperature@Starting 绕线开始温度 | D20: [°C] | K20: 0.00011574074
A21: Winding Temperature@8mins 8分钟后绕线温度 | D21: [°C] | K21: 0.00012731481
A22: Finnal stable Tempetature 最终稳定温度 | D22: [°C] | K22: 0.00013888889
A23: ∆T after 8mins 8分钟后的温差 | D23: [°C] | E23: =E22-G20 | K23: 0.00015046296
A24: Test Propose | K24: 0.00016203704
A25: The purpose of this test is to know the heat transfer performance of the DUT 测试目的是为了知道被测电机的传热性能 | K25: 0.00017361111
K26: 0.00018518519
B27: Automatic calculate 自动计算 | K27: 0.00019675926
K29: 0.00020833333
K30: 0.00021990741
K32: 0.00023148148
K33: 0.00024305556
K34: 0.00025462963
K35: 0.0002662037
K36: 0.00027777778
K37: 0.00028935185
K38: 0.00030092593
K39: 0.0003125
K40: 0.00032407407
K41: 0.00033564815
... K1880: 0.02162037

Sheet 9. Cont. Torque Curve
C1: PRODUCT ACCEPTANCE TEST - Continuous Torque Curve
C2: ='DUT Description'!C6&" - "&'DUT Description'!D6
A3: Item 9. Continue Torque Measurement 连续扭矩测量
A4: DUT 被测电机 | B4: Control model 控制模式 | G4: Traction & Torque主转扭矩 | I4: Traction & Torque主转扭矩 | K4: Traction & Torque主转扭矩
B5: Rotating direction 运转方向 | G5: Positive正转 | I5: Positive正转 | K5: Positive正转
B6: Speed Set Point 速度设定点 | F6: [rpm] | G6: 500 | I6: 6000 | K6: 10000
B7: Winding Temperature Target 绕线限制温度 | F7: [°C] | G7: 150
A9: Cooling System 冷却系统 | B9: DUT Flow Rate 被测电机流量 | F9: [lpm] | G9: 8
B10: DUT Coolant Pressure 被测电机冷却介质压力 | F10: [Kpa] | G10: <100
B11: Ambient Room Temperature 测试环境温度 | F11: [°C] | G11: 24.4
B12: DUT Coolant Inlet Temperature 被测电机输入冷却介质温度 | F12: [°C] | G12: 55
B13: MCU Flow Rate 负载电机流量 | F13: [lpm] | G13: 8
B14: MCU Coolant Inlet Temperature 负载电机输入冷却介质温度 | F14: [°C] | G14: 55
B15: Real Ambient Room Temperature 实际测试环境温度 | F15: [°C] | G15: 20 | I15: 20 | K15: 20
B16: Real DUT Flow Rate 实际被测电机流量 | F16: [lpm] | G16: 8 | I16: 8 | K16: 8
B17: Real DUT Coolant Inlet Temperature 实际被测电机输入冷却介质温度 | F17: [°C] | G17: 55 | I17: 55 | K17: 55
B18: Real DUT Coolant Outlet Temperature 实际被测电机输出冷却介质温度 | F18: [°C] | G18: 55 | I18: 55 | K18: 55
A20: Torque & Speed 扭矩和速度 | B20: Back EMF before test @1000 rpm 测试前1000转时的反电动势 | F20: [Vrms phph]
B21: Temperature for pre-back EMF test | F21: [°C]
B22: Winding Temp. RTD1 @Stable 绕线温度RTD1 | F22: [°C]
B23: Winding Temp. RTD2 @Stable 绕线温度RTD2 | F23: [°C]
B24: Real speed 实际速度 | F24: [rpm] | G24: 500 | I24: 6000 | K24: 10000
B25: Frequency 频率 | F25: [Hz] | G25: =G24/60*'DUT Description'!$D$8/2 | I25: =I24/60*'DUT Description'!$D$8/2 | K25: =K24/60*'DUT Description'!$D$8/2
B26: Torque Command 扭矩输入 | F26: [Nm]
B27: Torque Measurement 扭矩测量值
B28: DUT Shaft output Power 被测电机输出功率 | F28: [kW] | G28: =G24*G27*2*PI()/60/1000 | I28: =I24*I27*2*PI()/60/1000 | K28: =K24*K27*2*PI()/60/1000
B29: Back EMF after test @1000 rpm [Vrms phph] (quick!) 测试后1000转时的反电动势（测量速度快快快）
B30: Temperature for pos-back EMF test [°C]
A32: DC Link 直流连接 | B32: DC Voltage 直流电压 | F32: [V] | G32: 600 | I32: 600 | K32: 600
B33: DC Current 直流电流 | F33: [A]
B34: DC Power 直流功率 | F34: [kW] | G34: =IF(G33="","",G32*G33/1000) | I34: =IF(I33="","",I32*I33/1000) | K34: =IF(K33="","",K32*K33/1000)
A36: AC Parameters 交流电参数 | B36: Inverter Output Voltage ph-n 逆变器输出电压 | F36: [VRMS]
B37: Inverter Output Voltage (Fundamental ph-n) 逆变器输出电压 | F37: [VRMS]
B38: Inverter Output Current 逆变器输出电流 | F38: [ARMS]
B39: Inverter Output Current (Fundamental) [A] 逆变器输出电流 | F39: [ARMS]
B40: Inverter Output Power 逆变器输出功率 | F40: [kW]
B41: Inverter Output Power (Fundamental) 逆变器输出功率 | F41: [kW]
B42: Inverter Output Power Factor 逆变器输出功率系数
B43: Inverter Output Power Factor (Fundamental) 逆变器输出功率系数
A45: Efficiency 效率 | B45: Kt ideal@20°C & 1000 rpm | F45: [Nm/A] | G45: =IF(G20="","",SQRT(3)*G20/(2*PI()*1000/60)) | I45: =IF(I20="","",SQRT(3)*I20/(2*PI()*1000/60)) | K45: =IF(K20="","",SQRT(3)*K20/(2*PI()*1000/60))
...

Sheet Efficiency
A1: Test date
A2: Description
A3: Pole pairs | B3: 5 | C3: 5
A4: Machine model | B4: =IF(ABS(B27)<ABS(B38),"Motor","Regen") | C4: =IF(ABS(C27)<ABS(C38),"Motor","Regen")
A5: M.U.T. control mode | B5: Torque | C5: Torque
A6: Type of test | B6: Efficiency | C6: Efficiency
A7: Rotating direction
A8: Speed Set Point [rpm]
A9: Flow Rate Motor [l/min]
A10: Coolant Pressure [Kpa]
A11: Ambient Room Temperature [deg C]
A12: Coolant Temp. In Motor [deg C]
A13: Coolant Temp. Out Motor [deg C]
A14: Flow Rate Inverter [l/min]
A15: Coolant Temp. In Inverter [deg C]
A16: IGBT Temp. Inverter [deg C]
A17: Winding Temp. at end [deg C] | B17: 90 | C17: 88
A18: Back EMF before test [V] @1000 rpm | B18: 54.03 | C18: 54.03
A19: Temperature for pre-back EMF test [deg C] | B19: 51 | C19: 51
A20: Speed Read@Inverter Feedback [rpm]
A21: Frequency [Hz] | B21: =ABS(B20/60*B3) | C21: =ABS(C20/60*C3)
A22: Torque Sensor Offset [VDC]
A23: Torque Sensor DC Read Value [VDC]
A24: Torque measured value [VDC] | B24: =B23-B22 | C24: =C23-C22
A25: Torque sensor Gain | B25: 100.12 | C25: 100.12
A26: Torque Read@Torque Sensor [Nm] | B26: =B25*B24 | C26: =C25*C24
A27: Motor Power [kW] | B27: =B20*B26*2*PI()/60/1000 | C27: =C20*C26*2*PI()/60/1000
A28: Temperature for pos-back EMF test [deg C]
A29: Back EMF after test @1000 rpm [V] (quick!)
A30: DC Voltage [V] | B30: 600 | C30: 600
A31: DC Current [A]
A32: DC Power [kW] | B32: =B31*B30/1000 | C32: =C31*C30/1000
A33: DC Power Factor [] | B33: 1 | C33: 1
A34: Inverter Output Voltage ph-n [VRMS]
A35: Inverter Output Voltage (Fundamental ph-n) [VRMS]
A36: Inverter Output Current [A]
A37: Inverter Output Current (Fundamental) [A]
A38: Inverter Output Power [kW] (Fundamental)
A39: Inverter Output Power Factor []
A40: Inverter Output Power Factor [] (Fundamental)
...

Sheet 10.Efficiency Test
D1: PRODUCT ACCEPTANCE TEST - EFFICIENCY
D2: ='DUT Description'!D6&" - "&'DUT Description'!E6
A3: Item 10. Efficiency Measurement 效率测试
A4: Description | G4: Data 1 | H4: Data 2 | I4: Data 3 | J4: Data 4 | K4: Data 5 | L4: Data 6 | M4: Data 7 | N4: Data 8 | O4: Data 9 | P4: Data 10 | Q4: Data 11 | R4: Data 12 | S4: Data 13 | T4: Data 14 | U4: Data 15 | V4: Data 16 | W4: Data 13 | X4: Data 14 | Y4: Data 15 | Z4: Data 16
A5: DUT 被测电机 | B5: Speed Set Point 速度设定点 | F5: [rpm] | G5: 6500 | K5: 7000 | O5: 7500 | S5: 8000 | W5: 8500
B6: Torque Set Point 扭矩设置点 | F6: [Nm] | G6: 77 | H6: 66 | I6: 55 | J6: 44 | K6: 77 | L6: 66 | M6: 55 | N6: 44 | O6: 77 | P6: 66 | Q6: 55 | R6: 44 | S6: 77 | T6: 66 | U6: 55 | V6: 44 | W6: 77 | X6: 66 | Y6: 55 | Z6: 44
B7: Control model 控制模式 | G7: Traction & Torque主转扭矩 | H7: Traction & Torque主转扭矩 | I7: Traction & Torque主转扭矩 | J7: Traction & Torque主转扭矩 | K7: Traction & Torque主转扭矩 | L7: Traction & Torque主转扭矩 | M7: Traction & Torque主转扭矩 | N7: Traction & Torque主转扭矩 | O7: Traction & Torque主转扭矩 | P7: Traction & Torque主转扭矩 | Q7: Traction & Torque主转扭矩 | R7: Traction & Torque主转扭矩 | S7: Traction & Torque主转扭矩 | T7: Traction & Torque主转扭矩 | U7: Traction & Torque主转扭矩 | V7: Traction & Torque主转扭矩 | W7: Traction & Torque主转扭矩 | X7: Traction & Torque主转扭矩 | Y7: Traction & Torque主转扭矩 | Z7: Traction & Torque主转扭矩
B8: Rotating direction 运转方向 | G8: Positive正转 | H8: Positive正转 | I8: Positive正转 | J8: Positive正转 | K8: Positive正转 | L8: Positive正转 | M8: Positive正转 | N8: Positive正转 | O8: Positive正转 | P8: Positive正转 | Q8: Positive正转 | R8: Positive正转 | S8: Positive正转 | T8: Positive正转 | U8: Positive正转 | V8: Positive正转 | W8: Positive正转 | X8: Positive正转 | Y8: Positive正转 | Z8: Positive正转
B9: Winding Temperature Range 绕线温度范围 | F9: [°C] | G9: 80 to 120 | H9: 80 to 120 | I9: 80 to 120 | J9: 80 to 120 | K9: 80 to 120 | L9: 80 to 120 | M9: 80 to 120 | N9: 80 to 120 | O9: 80 to 120 | P9: 80 to 120 | Q9: 80 to 120 | R9: 80 to 120 | S9: 80 to 120 | T9: 80 to 120 | U9: 80 to 120 | V9: 80 to 120 | W9: 80 to 120 | X9: 80 to 120 | Y9: 80 to 120 | Z9: 80 to 120
A11: Cooling System 冷却系统 | B11: Ambient Room Temperature 测试环境温度 | F11: [°C] | G11: 20 | H11: 20 | I11: 20 | J11: 20 | K11: 20 | L11: 20 | M11: 20 | N11: 20 | O11: 20 | P11: 20 | Q11: 20 | R11: 20 | S11: 20 | T11: 20 | U11: 20 | V11: 20 | W11: 20 | X11: 20 | Y11: 20 | Z11: 20
B12: DUT Flow Rate [LPM] 被测电机流量 | F12: [Kpa] | G12: 8 | H12: 8 | I12: 8 | J12: 8 | K12: 8 | L12: 8 | M12: 8 | N12: 8 | O12: 8 | P12: 8 | Q12: 8 | R12: 8 | S12: 8 | T12: 8 | U12: 8 | V12: 8 | W12: 8 | X12: 8 | Y12: 8 | Z12: 8
B13: DUT Coolant Pressure 被测电机冷却介质压力 | F13: [Kpa] | G13: <100 | H13: <100 | I13: <100 | J13: <100 | K13: <100 | L13: <100 | M13: <100 | N13: <100 | O13: <100 | P13: <100 | Q13: <100 | R13: <100 | S13: <100 | T13: <100 | U13: <100 | V13: <100 | W13: <100 | X13: <100 | Y13: <100 | Z13: <100
B14: DUT Coolant Inlet Temperature 被测电机输入的冷却介质温度 | F14: [°C] | G14: 45 | H14: 45 | I14: 45 | J14: 45 | K14: 45 | L14: 45 | M14: 45 | N14: 45 | O14: 45 | P14: 45 | Q14: 45 | R14: 45 | S14: 45 | T14: 45 | U14: 45 | V14: 45 | W14: 45 | X14: 45 | Y14: 45 | Z14: 45
B15: MCU Flow Rate 负载电机流量 | F15: [LPM] | G15: 8 | H15: 8 | I15: 8 | J15: 8 | K15: 8 | L15: 8 | M15: 8 | N15: 8 | O15: 8 | P15: 8 | Q15: 8 | R15: 8 | S15: 8 | T15: 8 | U15: 8 | V15: 8 | W15: 8 | X15: 8 | Y15: 8 | Z15: 8
B16: MCU Coolant Inlet Temperature 负载电机输入的冷却介质温度 | F16: [°C] | G16: 20 | H16: 20 | I16: 20 | J16: 20 | K16: 20 | L16: 20 | M16: 20 | N16: 20 | O16: 20 | P16: 20 | Q16: 20 | R16: 20 | S16: 20 | T16: 20 | U16: 20 | V16: 20 | W16: 20 | X16: 20 | Y16: 20 | Z16: 20
B17: Real Ambient Room Temperature 实际测试环境温度 | F17: [°C] | G17: 21.7 | H17: 21.7 | I17: 21.7 | J17: 21.7 | K17: 21.7 | L17: 21.7 | M17: 21.7 | N17: 21.7 | O17: 21.7 | P17: 21.7 | Q17: 21.7 | R17: 21.7 | S17: 21.7 | T17: 21.7 | U17: 21.7 | V17: 21.7 | W17: 21.7 | X17: 21.7 | Y17: 21.7 | Z17: 21.7
B18: Real DUT Flow Rate 实际被测电机流量 | F18: [LPM] | G18: 8 | H18: 8 | I18: 8 | J18: 8 | K18: 8 | L18: 8 | M18: 8 | N18: 8 | O18: 8 | P18: 8 | Q18: 8 | R18: 8 | S18: 8 | T18: 8 | U18: 8 | V18: 8 | W18: 8 | X18: 8 | Y18: 8 | Z18: 8
B19: Real DUT Coolant Inlet Temperature 实际被测电机输入冷却介质温度 | F19: [°C] | G19: 45 | H19: 45 | I19: 45 | J19: 45 | K19: 45 | L19: 45 | M19: 45 | N19: 45 | O19: 45 | P19: 45 | Q19: 45 | R19: 45 | S19: 45 | T19: 45 | U19: 45 | V19: 45 | W19: 45 | X19: 45 | Y19: 45 | Z19: 45
A21: Torque & Speed 扭矩和速度 | B21: Back EMF before test @1000 rpm 测试前1000转时的反电动势 | F21: [Vrms phph]
B22: Temperature for pre-back EMF test | F22: [°C]
B23: Winding Temp. @Measuring 绕线温度测量值 | F23: [°C]
B24: Real speed 实际速度 | F24: [rpm] | G24: 6500 | H24: 6500 | I24: 6500 | J24: 6500 | K24: 7000 | L24: 7000 | M24: 7000 | N24: 7000 | O24: 7500 | P24: 7500 | Q24: 7500 | R24: 7500 | S24: 8000 | T24: 8000 | U24: 8000 | V24: 8000 | W24: 8500 | X24: 8500 | Y24: 8500 | Z24: 8500
B25: Frequency 频率 | F25: [Hz] | G25: =G24/60*'DUT Description'!$D$8/2 | H25: =H24/60*'DUT Description'!$D$8/2 | I25: =I24/60*'DUT Description'!$D$8/2 | J25: =J24/60*'DUT Description'!$D$8/2 | K25: =K24/60*'DUT Description'!$D$8/2 | L25: =L24/60*'DUT Description'!$D$8/2 | M25: =M24/60*'DUT Description'!$D$8/2 | N25: =N24/60*'DUT Description'!$D$8/2 | ... Z25: =Z24/60*'DUT Description'!$D$8/2
B26: Torque Command 扭矩命令 | F26: [Nm]
B27: Torque Measurement 扭矩测量值 | F27: [Nm]
B28: DUT Shaft output Power 被测电机轴输出功率 | F28: [kW] | G28: =G24*G27*2*PI()/60/1000 | H28: =H24*H27*2*PI()/60/1000 | I28: =I24*I27*2*PI()/60/1000 | J28: =J24*J27*2*PI()/60/1000 | K28: =K24*K27*2*PI()/60/1000 | L28: =L24*L27*2*PI()/60/1000 | M28: =M24*M27*2*PI()/60/1000 | N28: =N24*N27*2*PI()/60/1000 | ... Z28: =Z24*Z27*2*PI()/60/1000
B29: Back EMF after test @1000 rpm (quick!) 测试后1000转时的反电动势（速度快快快） | F29: [Vrms phph]
B30: Temperature for pos-back EMF test | F30: [°C]
A32: DC Link 直流连接 | B32: DC Voltage 直流电压 | F32: [V] | G32: 600 | H32: 600 | I32: 600 | J32: 600 | K32: 600 | L32: 600 | M32: 600 | N32: 600 | O32: 600 | P32: 600 | Q32: 600 | R32: 600 | S32: 600 | T32: 600 | U32: 600 | V32: 600 | W32: 600 | X32: 600 | Y32: 600 | Z32: 600
B33: DC Current 直流电流 | F33: [A]
B34: DC Power 直流功率 | F34: [kW] | G34: =IF(G33="","",G32*G33/1000) | H34: =IF(H33="","",H32*H33/1000) | I34: =IF(I33="","",I32*I33/1000) | J34: =IF(J33="","",J32*J33/1000) | K34: =IF(K33="","",K32*K33/1000) | L34: =IF(L33="","",L32*L33/1000) | M34: =IF(M33="","",M32*M33/1000) | N34: =IF(N33="","",N32*N33/1000) | ... Z34: =IF(Z33="","",Z32*Z33/1000)
A36: AC Parameters 交流参数 | B36: Inverter Output Voltage ph-n 逆变器输出电压 | F36: [VRMS]
B37: Inverter Output Voltage (Fundamental ph-n) 逆变器输出电压 | F37: [VRMS]
B38: Inverter Output Current 逆变器输出电流 | F38: [ARMS]
B39: Inverter Output Current (Fundamental) 逆变器输出电流 | F39: [ARMS]
B40: Inverter Output Power 逆变器输出功率 | F40: [kW]
B41: Inverter Output Power (Fundamental) 逆变器输出功率 | F41: [kW]
B42: Inverter Output Power Factor 逆变器输出功率系数 | F42: [%]
B43: Inverter Output Power Factor (Fundamental) 逆变器输出功率系数 | F43: [%]
A45: Efficiency 效率 | B45: Kt ideal@20°C & 1000 rpm | F45: [Nm/A] | G45: =IF(G21="","",SQRT(3)*G21/(2*PI()*1000/60))
...

Sheet 11. High Speed
D1: PRODUCT ACCEPTANCE TEST - High Speed
D2: ='DUT Description'!D6&" - "&'DUT Description'!E6
A3: Item 11. High Speed Test 高速测试
A5: Description | F5: Data 1 | I5: Time | J5: RTD1 | K5: RTD2
A6: Test Conditions 测试条件 | B6: D.U.T. control mode 被测电机控制模式 | F6: Disable 禁用 | I6: -7
B7: Rotating Direction 旋转方向 | F7: Positive正转 | I7: 1.1574074e-05
B8: Target test speed 测试速度目标 | E8: [rpm] | F8: 12000 | I8: 2.3148148e-05
B9: Running Time 运行时间 | E9: [mins] | F9: 5 | I9: 3.4722222e-05
B10: DUT Coolant Inlet Temperature 被测电机 | E10: [°C] | F10: 20 | I10: 4.6296296e-05
B11: DUT Coolant Flow Rate 被测电机流量 | E11: [LPM] | F11: 8 | I11: 5.787037e-05
B12: Winding Temperature @Starting 测试开始时的绕线温度 | E12: [°C] | F12: 35 ± 2 | I12: 6.9444444e-05
A13: Test Result 测试结果 | B13: Winding code 定子温度传感器代码 | F13: RTD1 | G13: RTD2 | I13: 8.1018519e-05
B14: Starting temperature 开始温度 | E14: [°C] | I14: 9.2592593e-05
B15: Real Speed 实际速度 | E15: [rpm] | F15: 12000 | I15: 0.00010416667
B16: Real Speed 实际角速度 | E16: [rad/s] | F16: =F15/60*2*PI() | I16: 0.00011574074
B17: Frequency 频率 | E17: [Hz] | F17: =F15*'DUT Description'!D8/60/2 | I17: 0.00012731481
B18: Torque Measurement 扭矩测量值 | E18: [Nm] | F18: 0.28 | I18: 0.00013888889
B19: Motor Power Loss 电机功率损失 | E19: [W] | F19: =F15*F18*2*PI()/60 | I19: 0.00015046296
B20: Winding Temperature @5mins 5分钟时的绕线温度 | E20: [°C] | I20: 0.00016203704
B21: Result [Pass/Failure] 结果 | F21: PASS | I21: 0.00017361111
I22: 0.00018518519
A23: Test Propose | I23: 0.00019675926
A24: the purpose of this test is to check motor mechanical part when spin in high speed. 1. check rotating part assembly. e.g.bearing, rotor… 2. check no load loss in high speed, pay attention on winding temperature of each stator after the testing. | I24: 0.00020833333
B25: Automatic calculate 自动计算 | I25: 0.00021990741
I26: 0.00023148148
I27: 0.00024305556
I28: 0.00025462963
I29: 0.0002662037
I30: 0.00027777778
I31: 0.00028935185
I32: 0.00030092593
I33: 0.0003125
I34: 0.00032407407
I35: 0.00033564815
I36: 0.00034722222
I37: 0.0003587963
... I475: 0.0054282407

Sheet 12.Work Area Check
D1: PRODUCT ACCEPTANCE TEST - Work Area Check
D2: ='DUT Description'!D6&" - "&'DUT Description'!E6
A3: Item 12. Work Area Check - Only for Dual Motor or Special Test 双电机或特殊电机的工作区域检查
A4: DC Voltage Setup [V] 直流电压 | C4: 400
A5: Dyno Control model 测功机控制模式 | C5: Generation & Speed发电速度
A6: DUT - Front Control model 被测电机-前电机控制模式 | C6: Traction & Torque主转扭矩
A7: DUT - Rear Control model 被测电机-后电机控制模式 | C7: Traction & Torque主转扭矩
A8: Cooling Setup 冷却系统 | C8: Front Motor 前电机 | D8: Rear Motor 后电机
A9: DUT Flow Rate [LPM] 被测电机冷却介质流量 | C9: ='11. High Speed'!F11 | D9: 10
A10: DUT Coolant Pressure [Kpa] 被测电机冷却介质压力 | C10: <100 | D10: <100
A11: Ambient Room Temperature [°C] 测试环境温度 | C11: 20 | D11: 20
A12: DUT Coolant Inlet Temperature [°C] 被测电机冷却介质进入温度 | C12: 20 | D12: 20
A13: MCU Flow Rate [LPM] 逆变器冷却介质流量 | C13: 20 | D13: 20
A14: MCU Coolant Inlet Temperature [°C] 逆变器冷却介质进入温度 | C14: 20 | D14: 20
A15: Step | B15: Dyno 测功机 | E15: Device Under Test 被测电机 | Q15: Result 结果 | R15: Comments 说明
E16: Front Motor 前电机 | I16: Rear Motor 后电机 | M16: Total Torque & Power 总扭矩和功率
B17: Speed Command [rpm] 速度命令 | C17: Feedback Speed 反馈速度[rpm] | D17: Feedback Torque 反馈扭矩[Nm] | E17: Torque Command 扭矩命令 [Nm] | F17: Feedback Torque 反馈扭矩[Nm] | G17: Feedback speed 反馈速度[rpm] | H17: Motor Temp. 前电机温度[°C] | I17: Torque Command 扭矩命令[Nm] | J17: Feedback Torque 反馈扭矩[Nm] | K17: Feedback speed 反馈速度[rpm] | L17: Motor Temp. 后电机温度 [°C] | M17: Torque Sensor Offset [VDC] 扭矩传感器补偿值 | N17: Torque Sensor DC Read [VDC] 扭矩传感器直流值 | O17: Torque Measurement 扭矩测量值 | P17: DUT Shaft output Power [kW] 被测电机轴输出功率 | Q17: [Pass/Failure] 通过/不通过
A18: 1 | B18: 1000 | C18: 1000 | E18: 50 | I18: =E18 | M18: 0 | N18: 0.5 | O18: =(N18-M18)*100.12 | P18: =G18*O18*2*PI()/60/1000 | Q18: PASS
A19: 2 | B19: 1000 | C19: 1000 | E19: 100 | I19: =E19 | M19: 0 | N19: 1 | O19: =(N19-M19)*100.12 | P19: =G19*O19*2*PI()/60/1000 | Q19: PASS
A20: 3 | B20: 1000 | C20: 1000 | E20: 150 | I20: =E20 | M20: 0 | N20: 1.5 | O20: =(N20-M20)*100.12 | P20: =G20*O20*2*PI()/60/1000 | Q20: PASS
A21: 4 | B21: 2000 | C21: 2000 | E21: 50 | I21: =E21 | M21: 0 | N21: 0.5 | O21: =(N21-M21)*100.12 | P21: =G21*O21*2*PI()/60/1000 | Q21: PASS
A22: 5 | B22: 2000 | C22: 2000 | E22: 100 | I22: =E22 | M22: 0 | N22: 1 | O22: =(N22-M22)*100.12 | P22: =G22*O22*2*PI()/60/1000 | Q22: PASS
A23: 6 | B23: 2000 | C23: 2000 | E23: 150 | I23: =E23 | M23: 0 | N23: 1.5 | O23: =(N23-M23)*100.12 | P23: =G23*O23*2*PI()/60/1000 | Q23: PASS
A24: 7 | B24: 3000 | C24: 3000 | E24: 50 | I24: =E24 | M24: 0 | N24: 0.5 | O24: =(N24-M24)*100.12 | P24: =G24*O24*2*PI()/60/1000 | Q24: PASS
A25: 8 | B25: 3000 | C25: 3000 | E25: 100 | I25: =E25 | M25: 0 | N25: 1 | O25: =(N25-M25)*100.12 | P25: =G25*O25*2*PI()/60/1000 | Q25: PASS
A26: 9 | B26: 3000 | C26: 3000 | E26: 150 | I26: =E26 | M26: 0 | N26: 1.5 | O26: =(N26-M26)*100.12 | P26: =G26*O26*2*PI()/60/1000 | Q26: PASS
A27: 10 | B27: 4000 | C27: 4000 | E27: 50 | I27: =E27 | M27: 0 | N27: 0.5 | O27: =(N27-M27)*100.12 | P27: =G27*O27*2*PI()/60/1000 | Q27: PASS
A28: 11 | B28: 4000 | C28: 4000 | E28: 100 | I28: =E28 | M28: 0 | N28: 1 | O28: =(N28-M28)*100.12 | P28: =G28*O28*2*PI()/60/1000 | Q28: PASS
A29: 12 | B29: 4000 | C29: 4000 | E29: 150 | I29: =E29 | M29: 0 | N29: 1.5 | O29: =(N29-M29)*100.12 | P29: =G29*O29*2*PI()/60/1000 | Q29: PASS
... A64: 47 | B64: -1000 | C64: -1000 | E64: -50 | I64: =E64 | M64: 0 | N64: -0.5 | O64: =(N64-M64)*100.12 | P64: =G64*O64*2*PI()/60/1000 | Q64: PASS

Sheet List
A1: Model | B1: Product Number
A2: M21S5-D-18LHYY | B2: M88-000002
A3: M21S5-D-18RHYY | B3: M88-000003
A4: M21P5-S-18XXYY | B4: M88-000004
A5: M24P5-S-18XXYY | B5: M88-000005
A6: M19P5-S-18XXYY | B6: M88-000006
A7: M21P3-S-19NBLI | B7: M88-000007
B8: M88-000008
B9: M88-000009
B10: M88-000010
B11: M88-000011
B12: M88-000012
B13: M88-000013
B14: M88-000014
B15: M88-000015
B16: M88-000016
B17: M88-000017
B18: M88-000018
B19: M88-000019
... B35: M88-000035
